<?xml version="1.0" ?>
<robot name="base_link" xmlns:xacro="http://www.ros.org/wiki/xacro">

<xacro:include filename="$(find base_link_description)/urdf/materials.xacro" />
<xacro:include filename="$(find base_link_description)/urdf/base_link.trans" />
<xacro:include filename="$(find base_link_description)/urdf/base_link.gazebo" />
<link name="base_link">
  <inertial>
    <origin xyz="-0.0022157875746322956 -3.4601102738784125e-17 0.04683880069435151" rpy="0 0 0"/>
    <mass value="1.0316915999493312"/>
    <inertia ixx="0.001108" iyy="0.004172" izz="0.004984" ixy="-0.0" iyz="-0.0" ixz="-8e-06"/>
  </inertial>
  <visual>
    <origin xyz="0 0 0" rpy="0 0 0"/>
    <geometry>
      <mesh filename="package://base_link_description/meshes/base_link.stl" scale="0.001 0.001 0.001"/>
    </geometry>
    <material name="silver"/>
  </visual>
  <collision>
    <origin xyz="0 0 0" rpy="0 0 0"/>
    <geometry>
      <mesh filename="package://base_link_description/meshes/base_link.stl" scale="0.001 0.001 0.001"/>
    </geometry>
  </collision>
</link>

<link name="right_wheel_1">
  <inertial>
    <origin xyz="4.537477480137664e-07 -0.0025002831323025568 -3.469446951953614e-18" rpy="0 0 0"/>
    <mass value="0.11097676048805946"/>
    <inertia ixx="2.5e-05" iyy="5e-05" izz="2.5e-05" ixy="-0.0" iyz="0.0" ixz="0.0"/>
  </inertial>
  <visual>
    <origin xyz="0.080166 0.055284 -0.03" rpy="0 0 0"/>
    <geometry>
      <mesh filename="package://base_link_description/meshes/right_wheel_1.stl" scale="0.001 0.001 0.001"/>
    </geometry>
    <material name="silver"/>
  </visual>
  <collision>
    <origin xyz="0.080166 0.055284 -0.03" rpy="0 0 0"/>
    <geometry>
      <mesh filename="package://base_link_description/meshes/right_wheel_1.stl" scale="0.001 0.001 0.001"/>
    </geometry>
  </collision>
</link>

<link name="left_wheel_1">
  <inertial>
    <origin xyz="4.5374774781947735e-07 0.0025002831323025568 -3.469446951953614e-18" rpy="0 0 0"/>
    <mass value="0.11097676048805946"/>
    <inertia ixx="2.5e-05" iyy="5e-05" izz="2.5e-05" ixy="0.0" iyz="-0.0" ixz="-0.0"/>
  </inertial>
  <visual>
    <origin xyz="0.080166 -0.055284 -0.03" rpy="0 0 0"/>
    <geometry>
      <mesh filename="package://base_link_description/meshes/left_wheel_1.stl" scale="0.001 0.001 0.001"/>
    </geometry>
    <material name="silver"/>
  </visual>
  <collision>
    <origin xyz="0.080166 -0.055284 -0.03" rpy="0 0 0"/>
    <geometry>
      <mesh filename="package://base_link_description/meshes/left_wheel_1.stl" scale="0.001 0.001 0.001"/>
    </geometry>
  </collision>
</link>

<link name="lidar_1">
  <inertial>
    <origin xyz="4.537477479929497e-07 -2.220446049250313e-18 0.015" rpy="0 0 0"/>
    <mass value="0.4624031687002476"/>
    <inertia ixx="0.000107" iyy="0.000107" izz="0.000145" ixy="-0.0" iyz="-0.0" ixz="0.0"/>
  </inertial>
  <visual>
    <origin xyz="-0.049834 0.0 -0.075" rpy="0 0 0"/>
    <geometry>
      <mesh filename="package://base_link_description/meshes/lidar_1.stl" scale="0.001 0.001 0.001"/>
    </geometry>
    <material name="silver"/>
  </visual>
  <collision>
    <origin xyz="-0.049834 0.0 -0.075" rpy="0 0 0"/>
    <geometry>
      <mesh filename="package://base_link_description/meshes/lidar_1.stl" scale="0.001 0.001 0.001"/>
    </geometry>
  </collision>
</link>

<link name="mount_1">
  <inertial>
    <origin xyz="-0.049999546252252065 -1.3322676295501878e-17 -0.04108018704276195" rpy="0 0 0"/>
    <mass value="0.48439014073208936"/>
    <inertia ixx="0.000144" iyy="0.000144" izz="0.00026" ixy="-0.0" iyz="-0.0" ixz="0.0"/>
  </inertial>
  <visual>
    <origin xyz="-0.099834 -0.0 -0.105" rpy="0 0 0"/>
    <geometry>
      <mesh filename="package://base_link_description/meshes/mount_1.stl" scale="0.001 0.001 0.001"/>
    </geometry>
    <material name="silver"/>
  </visual>
  <collision>
    <origin xyz="-0.099834 -0.0 -0.105" rpy="0 0 0"/>
    <geometry>
      <mesh filename="package://base_link_description/meshes/mount_1.stl" scale="0.001 0.001 0.001"/>
    </geometry>
  </collision>
</link>

<joint name="Rev1" type="continuous">
  <origin xyz="-0.080166 -0.055284 0.03" rpy="0 0 0"/>
  <parent link="base_link"/>
  <child link="right_wheel_1"/>
  <axis xyz="0.0 1.0 0.0"/>
</joint>

<joint name="Rev2" type="continuous">
  <origin xyz="-0.080166 0.055284 0.03" rpy="0 0 0"/>
  <parent link="base_link"/>
  <child link="left_wheel_1"/>
  <axis xyz="0.0 1.0 0.0"/>
</joint>

<joint name="Rev3" type="continuous">
  <origin xyz="-0.05 -0.0 -0.03" rpy="0 0 0"/>
  <parent link="mount_1"/>
  <child link="lidar_1"/>
  <axis xyz="0.0 0.0 1.0"/>
</joint>

<joint name="Rigid4" type="fixed">
  <origin xyz="0.099834 0.0 0.105" rpy="0 0 0"/>
  <parent link="base_link"/>
  <child link="mount_1"/>
</joint>

</robot>
